{
 "cells": [
  {
   "cell_type": "code",
   "execution_count": 1,
   "metadata": {},
   "outputs": [],
   "source": [
    "import numpy as np\n",
    "from matplotlib import pyplot as plt\n",
    "import pickle\n",
    "from helper_fn import data_import, relabel"
   ]
  },
  {
   "cell_type": "code",
   "execution_count": 2,
   "metadata": {},
   "outputs": [],
   "source": [
    "from tensorflow.keras.models import load_model"
   ]
  },
  {
   "cell_type": "code",
   "execution_count": 3,
   "metadata": {},
   "outputs": [],
   "source": [
    "test_path='/Users/raunavghosh/Documents/DeepLearning/Assignments/Deep-Learning-and-Applications-CS671/ProgrammingAssignment4/Group_10/test'\n",
    "train_path='/Users/raunavghosh/Documents/DeepLearning/Assignments/Deep-Learning-and-Applications-CS671/ProgrammingAssignment4/Group_10/train'\n",
    "val_path='/Users/raunavghosh/Documents/DeepLearning/Assignments/Deep-Learning-and-Applications-CS671/ProgrammingAssignment4/Group_10/val'\n",
    "\n",
    "#import datasets\n",
    "train_data, train_labels = data_import(train_path)\n",
    "test_data, test_labels = data_import(test_path)\n",
    "val_data, val_labels = data_import(val_path)\n",
    "\n",
    "train_labels = relabel(train_labels)\n",
    "test_labels = relabel(test_labels)\n",
    "val_labels = relabel(val_labels)\n"
   ]
  },
  {
   "attachments": {},
   "cell_type": "markdown",
   "metadata": {},
   "source": [
    "# PCA Task1"
   ]
  },
  {
   "cell_type": "code",
   "execution_count": 6,
   "metadata": {},
   "outputs": [
    {
     "name": "stderr",
     "output_type": "stream",
     "text": [
      "2023-04-09 13:20:53.627114: W tensorflow/tsl/platform/profile_utils/cpu_utils.cc:128] Failed to get CPU frequency: 0 Hz\n"
     ]
    },
    {
     "ename": "ValueError",
     "evalue": "in user code:\n\n    File \"/Users/raunavghosh/miniconda3/envs/.env/lib/python3.10/site-packages/keras/engine/training.py\", line 1820, in test_function  *\n        return step_function(self, iterator)\n    File \"/Users/raunavghosh/miniconda3/envs/.env/lib/python3.10/site-packages/keras/engine/training.py\", line 1804, in step_function  **\n        outputs = model.distribute_strategy.run(run_step, args=(data,))\n    File \"/Users/raunavghosh/miniconda3/envs/.env/lib/python3.10/site-packages/keras/engine/training.py\", line 1792, in run_step  **\n        outputs = model.test_step(data)\n    File \"/Users/raunavghosh/miniconda3/envs/.env/lib/python3.10/site-packages/keras/engine/training.py\", line 1756, in test_step\n        y_pred = self(x, training=False)\n    File \"/Users/raunavghosh/miniconda3/envs/.env/lib/python3.10/site-packages/keras/utils/traceback_utils.py\", line 70, in error_handler\n        raise e.with_traceback(filtered_tb) from None\n    File \"/Users/raunavghosh/miniconda3/envs/.env/lib/python3.10/site-packages/keras/engine/input_spec.py\", line 295, in assert_input_compatibility\n        raise ValueError(\n\n    ValueError: Input 0 of layer \"Model-PCA32\" is incompatible with the layer: expected shape=(None, 32), found shape=(None, 28, 28)\n",
     "output_type": "error",
     "traceback": [
      "\u001b[0;31m---------------------------------------------------------------------------\u001b[0m",
      "\u001b[0;31mValueError\u001b[0m                                Traceback (most recent call last)",
      "Cell \u001b[0;32mIn[6], line 2\u001b[0m\n\u001b[1;32m      1\u001b[0m model \u001b[39m=\u001b[39m load_model(\u001b[39m\"\u001b[39m\u001b[39m/Users/raunavghosh/Documents/DeepLearning/Assignments/Deep-Learning-and-Applications-CS671/ProgrammingAssignment4/pca_models/pcamodel_32.h5\u001b[39m\u001b[39m\"\u001b[39m)\n\u001b[0;32m----> 2\u001b[0m model\u001b[39m.\u001b[39;49mevaluate(test_data, test_labels)\n",
      "File \u001b[0;32m~/miniconda3/envs/.env/lib/python3.10/site-packages/keras/utils/traceback_utils.py:70\u001b[0m, in \u001b[0;36mfilter_traceback.<locals>.error_handler\u001b[0;34m(*args, **kwargs)\u001b[0m\n\u001b[1;32m     67\u001b[0m     filtered_tb \u001b[39m=\u001b[39m _process_traceback_frames(e\u001b[39m.\u001b[39m__traceback__)\n\u001b[1;32m     68\u001b[0m     \u001b[39m# To get the full stack trace, call:\u001b[39;00m\n\u001b[1;32m     69\u001b[0m     \u001b[39m# `tf.debugging.disable_traceback_filtering()`\u001b[39;00m\n\u001b[0;32m---> 70\u001b[0m     \u001b[39mraise\u001b[39;00m e\u001b[39m.\u001b[39mwith_traceback(filtered_tb) \u001b[39mfrom\u001b[39;00m \u001b[39mNone\u001b[39m\n\u001b[1;32m     71\u001b[0m \u001b[39mfinally\u001b[39;00m:\n\u001b[1;32m     72\u001b[0m     \u001b[39mdel\u001b[39;00m filtered_tb\n",
      "File \u001b[0;32m/var/folders/xb/h53k7r3j5_55k9r3s9dzr_tr0000gn/T/__autograph_generated_filezy5atnos.py:15\u001b[0m, in \u001b[0;36mouter_factory.<locals>.inner_factory.<locals>.tf__test_function\u001b[0;34m(iterator)\u001b[0m\n\u001b[1;32m     13\u001b[0m \u001b[39mtry\u001b[39;00m:\n\u001b[1;32m     14\u001b[0m     do_return \u001b[39m=\u001b[39m \u001b[39mTrue\u001b[39;00m\n\u001b[0;32m---> 15\u001b[0m     retval_ \u001b[39m=\u001b[39m ag__\u001b[39m.\u001b[39mconverted_call(ag__\u001b[39m.\u001b[39mld(step_function), (ag__\u001b[39m.\u001b[39mld(\u001b[39mself\u001b[39m), ag__\u001b[39m.\u001b[39mld(iterator)), \u001b[39mNone\u001b[39;00m, fscope)\n\u001b[1;32m     16\u001b[0m \u001b[39mexcept\u001b[39;00m:\n\u001b[1;32m     17\u001b[0m     do_return \u001b[39m=\u001b[39m \u001b[39mFalse\u001b[39;00m\n",
      "\u001b[0;31mValueError\u001b[0m: in user code:\n\n    File \"/Users/raunavghosh/miniconda3/envs/.env/lib/python3.10/site-packages/keras/engine/training.py\", line 1820, in test_function  *\n        return step_function(self, iterator)\n    File \"/Users/raunavghosh/miniconda3/envs/.env/lib/python3.10/site-packages/keras/engine/training.py\", line 1804, in step_function  **\n        outputs = model.distribute_strategy.run(run_step, args=(data,))\n    File \"/Users/raunavghosh/miniconda3/envs/.env/lib/python3.10/site-packages/keras/engine/training.py\", line 1792, in run_step  **\n        outputs = model.test_step(data)\n    File \"/Users/raunavghosh/miniconda3/envs/.env/lib/python3.10/site-packages/keras/engine/training.py\", line 1756, in test_step\n        y_pred = self(x, training=False)\n    File \"/Users/raunavghosh/miniconda3/envs/.env/lib/python3.10/site-packages/keras/utils/traceback_utils.py\", line 70, in error_handler\n        raise e.with_traceback(filtered_tb) from None\n    File \"/Users/raunavghosh/miniconda3/envs/.env/lib/python3.10/site-packages/keras/engine/input_spec.py\", line 295, in assert_input_compatibility\n        raise ValueError(\n\n    ValueError: Input 0 of layer \"Model-PCA32\" is incompatible with the layer: expected shape=(None, 32), found shape=(None, 28, 28)\n"
     ]
    }
   ],
   "source": [
    "model = load_model(\"/Users/raunavghosh/Documents/DeepLearning/Assignments/Deep-Learning-and-Applications-CS671/ProgrammingAssignment4/pca_models/pcamodel_32.h5\")\n",
    "model.evaluate(test_data, test_labels)"
   ]
  },
  {
   "cell_type": "code",
   "execution_count": null,
   "metadata": {},
   "outputs": [],
   "source": []
  }
 ],
 "metadata": {
  "kernelspec": {
   "display_name": ".env",
   "language": "python",
   "name": "python3"
  },
  "language_info": {
   "codemirror_mode": {
    "name": "ipython",
    "version": 3
   },
   "file_extension": ".py",
   "mimetype": "text/x-python",
   "name": "python",
   "nbconvert_exporter": "python",
   "pygments_lexer": "ipython3",
   "version": "3.10.9"
  },
  "orig_nbformat": 4
 },
 "nbformat": 4,
 "nbformat_minor": 2
}
